<mujoco>

	<visual>
			<headlight ambient="0.25 0.25 0.25"/>
	</visual>

	<option timestep="0.0001" integrator="RK4" gravity="0 0 -9.81">
		<flag sensornoise="disable" contact="enable" energy="enable"/>
	</option>

	<worldbody>
		<geom type="plane" size="5 5 0.1" rgba=".9 0.9 0.9 1"/>

		<body name="leg1" pos="0 0 .75" euler="0 0 0">
			<joint name="x" type="slide" pos="0 0 0.5" axis = "1 0 0" />
			<!-- <joint name="y" type="slide" pos="0 0 0.5" axis = "0 1 0" /> -->
			<joint name="z" type="slide" pos="0 0 0.5" axis = "0 0 1" />
			<joint name="pin" type="hinge" pos="0 0 0.5" axis="0 -1 0" />
			<geom type="cylinder" size=".05 .5" rgba="0 .9 0 1" mass="1"/>
			<body name="foot1" pos="0 0 -0.75">
				<joint name ="knee1" type="slide" pos="0 0 0.25" axis="0 0 -1"/>
				<geom type="sphere" size=".05" rgba="0.9 .9 0 1" mass="0.1"/>
			</body>
			<body name="leg2" pos="0 0.25 0" euler="0 0 0">
				<geom type="cylinder" size=".05 .5" rgba=".9 0 0 1" mass="1"/>
				<joint name="hip" type="hinge" pos="0 0 0.5" axis="0 -1 0" />
				<body name="foot2" pos="0 0 -0.75">
					<joint name="knee2" type="slide" pos="0 0 0.25" axis="0 0 -1"/>
					<geom type="sphere" size ="0.05" rgba=".9 .9 0 1" mass="0.1"/>
				</body>
			</body>
		</body>

	</worldbody>

	<!-- <equality>
			<connect body1='leg1' body2='world' anchor='0 0 0.5'/>
	</equality> -->

	<actuator>
		<position name="pservo_hip" joint="hip" kp="10000"/>
		<velocity name="vservo_hip" joint="hip" kv="1000"/>
		<position name="pservo_knee1" joint="knee1" kp="1000"/>
		<velocity name="vservo_knee1" joint="knee1" kv="100"/>
		<position name="pservo_knee2" joint="knee2" kp="1000"/>
		<velocity name="vservo_knee2" joint="knee2" kv="100"/>
		<!-- <position name="init_pservo_leg1" joint="pin" kp="100"/>
		<velocity name="init_vservo_leg1" joint="pin" kv="10"/> -->
	</actuator>


</mujoco>
